<?xml version="1.0" ?>

<robot name="my_mm_robot" xmlns:xacro="https://www.ros.org/wiki/xacro" >
    
  <material name="black">
    <color rgba="0.0 0.0 0.0 1.0"/>
  </material>
  <material name="blue">
    <color rgba="0.203125 0.23828125 0.28515625 1.0"/>
  </material>
  <material name="green">
    <color rgba="0.0 0.8 0.0 1.0"/>
  </material>
  <material name="grey">
    <color rgba="0.2 0.2 0.2 1.0"/>
  </material>
  <material name="orange">
    <color rgba="1.0 0.423529411765 0.0392156862745 1.0"/>
  </material>
  <material name="brown">
    <color rgba="0.870588235294 0.811764705882 0.764705882353 1.0"/>
  </material>
  <material name="red">
    <color rgba="0.80078125 0.12890625 0.1328125 1.0"/>
  </material>
  <material name="white">
    <color rgba="1.0 1.0 1.0 1.0"/>
  </material>  
  
  <gazebo reference="link_chassis">
    <material>Gazebo/Orange</material>
  </gazebo>
  <gazebo reference="link_left_wheel">
    <material>Gazebo/Black</material>
  </gazebo>
  <gazebo reference="link_right_wheel">
    <material>Gazebo/Black</material>
  </gazebo>
    
  <link name="link_chassis">
    <!-- pose and inertial -->
    <pose>0 0 0.1 0 0 0</pose>
    
    <inertial>
      <mass value="0.5"/>
      <origin rpy="0  0  0" xyz="0 0.01 0"/>
      <inertia ixx="0.00022083" ixy="0" ixz="0" iyy="0.00022083" iyz="0" izz="0.00040833"/>
    </inertial>
    
    <collision name="link_chassis_collision">
      <origin rpy="0  0  0" xyz="0     0    -0.005"/>
      <geometry>
        <box size="0.07 0.07 0.02"/>
      </geometry>
    </collision>
    
    <visual name="link_chassis_visual">
      <origin rpy="0  0  0" xyz="0     0    -0.005"/>
      <geometry>
        <box size="0.07 0.07 0.02"/>
      </geometry>
    </visual>
    
    <!-- caster front -->
    <collision name="caster_front_collision">
      <origin rpy="0  0  0" xyz="0     -0.03  -0.015"/>
      <geometry>
        <sphere radius="0.005"/>
      </geometry>
      <surface>
        <friction>
          <ode>
            <mu>100</mu>
            <mu2>100</mu2>
            <slip1>1000.0</slip1>
            <slip2>1000.0</slip2>
          </ode>
        </friction>
      </surface>
    </collision>
    
    <visual name="castor_front_visual">
      <origin rpy="0  0  0" xyz="0   -0.03  -0.015"/>
      <geometry>
        <sphere radius="0.005"/>
      </geometry>
    </visual>
</link>
  
  <!-- Create wheel right -->  
    
  <link name="link_right_wheel">    
    <inertial>
      <mass value="0.2"/>
      <origin rpy="0 1.5707 0" xyz="0 0 0"/>
      <inertia ixx="2.3e-06" ixy="0" ixz="0" iyy="2.3e-06" iyz="0" izz="4.5e-06"/>
    </inertial>
    
    <collision name="link_right_wheel_collision">
      <origin rpy="0 1.5707 0" xyz="0 0 0"/>
      <geometry>
        <cylinder length="0.01" radius="0.02"/>
      </geometry>
    </collision>
    
    <visual name="link_right_wheel_visual">
      <origin rpy="0 1.5707 0" xyz="0 0 0"/>
      <geometry>
        <cylinder length="0.01" radius="0.02"/>
      </geometry>      
    </visual>
    
  </link>
    
  <!--   Joint for right wheel  -->
  <joint name="joint_right_wheel" type="continuous">
    <origin rpy="0 0 0" xyz="-0.04  0.02    0"/>
    <child link="link_right_wheel" />
    <parent link="link_chassis"/>
    <axis rpy="0 0 0" xyz="1 0 0"/>
    <limit effort="5" velocity="6"/>
    <joint_properties damping="10000.0" friction="10000.0" />
  </joint>  
  <transmission name="right_wheel_trans">
     <type>transmission_interface/SimpleTransmission</type>
     <actuator name="right_wheel_motor">
       <hardwareInterface>VelocityJointInterface</hardwareInterface>
       <mechanicalReduction>7</mechanicalReduction>
     </actuator>
     <joint name="joint_right_wheel">
       <hardwareInterface>VelocityJointInterface</hardwareInterface>
     </joint>
  </transmission>
    
  <!-- Left Wheel link -->
    
  <link name="link_left_wheel">    
    <inertial>
      <mass value="0.2"/>
      <origin rpy="0 1.5707 0" xyz="0 0 0"/>
      <inertia ixx="2.3e-06" ixy="0" ixz="0" iyy="2.3e-06" iyz="0" izz="4.5e-06"/>
    </inertial>
    
    <collision name="link_left_wheel_collision">
      <origin rpy="0 1.5707 0" xyz="0 0 0"/>
      <geometry>
        <cylinder length="0.01" radius="0.02"/>
      </geometry>
    </collision>
    
    <visual name="link_left_wheel_visual">
      <origin rpy="0 1.5707 0" xyz="0 0 0"/>
      <geometry>
        <cylinder length="0.01" radius="0.02"/>
      </geometry>      
    </visual>
    
  </link>
    
  <!--   Joint for right wheel  -->
  <joint name="joint_left_wheel" type="continuous">
    <origin rpy="0 0 0" xyz="0.04 0.02 0"/>
    <child link="link_left_wheel" />
    <parent link="link_chassis"/>
    <axis rpy="0 0 0" xyz="1 0 0"/>
    <limit effort="5" velocity="6"/>
    <joint_properties damping="10000.0" friction="10000.0" />
  </joint> 
  <transmission name="left_wheel_trans">
     <type>transmission_interface/SimpleTransmission</type>
     <actuator name="left_wheel_motor">
       <hardwareInterface>VelocityJointInterface</hardwareInterface>
       <mechanicalReduction>7</mechanicalReduction>
     </actuator>
     <joint name="joint_left_wheel">
       <hardwareInterface>VelocityJointInterface</hardwareInterface>
     </joint>
  </transmission>


  <gazebo>
    <plugin filename="libgazebo_ros_diff_drive.so" name="differential_drive_controller">
      <alwaysOn>true</alwaysOn>
      <updateRate>20</updateRate>
      <leftJoint>joint_left_wheel</leftJoint>
      <rightJoint>joint_right_wheel</rightJoint>
      <wheelSeparation>0.4</wheelSeparation>
      <wheelDiameter>0.2</wheelDiameter>
      <torque>0.1</torque>
      <commandTopic>cmd_vel</commandTopic>
      <odometryTopic>odom</odometryTopic>
      <odometryFrame>odom</odometryFrame>
      <robotBaseFrame>link_chassis</robotBaseFrame>
    </plugin>
  </gazebo>



    <!-- 
    Adding a laser scan sensor to the robot 
  -->
  <link name="sensor_laser">
    <inertial>
      <origin xyz="0 0 0" rpy="0 0 0" />
      <mass value="0.01" />
      <inertia ixx="0.02" ixy="0" ixz="0" iyy="0.02" iyz="0" izz="0.02"/> 
    </inertial>

    <visual>
      <origin xyz="0.02 0 0" rpy="0 0 0" />
      <geometry>
        <cylinder radius="0.005" length="0.02"/>
      </geometry>
      <material name="white" />
    </visual>

    <collision>
      <origin xyz="0 0 0" rpy="0 0 0"/>
      <geometry>
        <cylinder radius="0.005" length="0.001"/>
      </geometry>
    </collision>
  </link>

  <joint name="joint_sensor_laser" type="fixed">
    <origin rpy="0  0  -1.57" xyz="0    0    0.01"/>
    <parent link="link_chassis"/>
    <child link="sensor_laser"/>
  </joint>


  <gazebo reference="sensor_laser">
    <sensor type="ray" name="head_hokuyo_sensor">
      <pose>0 0 0 0 0 0</pose>
      <visualize>true</visualize>
      <update_rate>20</update_rate>
      <ray>
        <scan>
          <horizontal>
            <samples>360</samples>
            <resolution>1</resolution>
            <min_angle>-1.570796</min_angle>
            <max_angle>1.570796</max_angle>
          </horizontal>
        </scan>
        <range>
          <min>0.04</min>
          <max>10.0</max>
          <resolution>0.01</resolution>
        </range>
      </ray>
      <plugin name="gazebo_ros_head_hokuyo_controller" filename="libgazebo_ros_laser.so">
        <topicName>/my_mm_robot/laser/scan</topicName>
        <frameName>sensor_laser</frameName>
      </plugin>
    </sensor>
  </gazebo>




  <!-- Camera -->
  <link name="camera_link">
    <collision>
      <origin xyz="1 0 0" rpy="0 0 0"/>
      <geometry>
    <box size="0.01 0.01 0.01"/>
      </geometry>
    </collision>

    <visual>
      <origin xyz="0 0 0" rpy="0 0 0"/>
      <geometry>
    <box size="0.1 0.1 0.1"/>
      </geometry>
      <material name="red"/>
    </visual>

    <inertial>
      <mass value="1e-5" />
      <origin xyz="0 0 0" rpy="0 0 0"/>
      <inertia ixx="1e-6" ixy="0" ixz="0" iyy="1e-6" iyz="0" izz="1e-6" />
    </inertial>
  </link>

  <joint name="camera_joint" type="fixed">
    <axis xyz="0 1 0" />
    <origin xyz="0 0 0.5" rpy="0 0 0"/>
    <parent link="link_chassis"/>
    <child link="camera_link"/>
  </joint>


 <gazebo reference="camera_link">
    <sensor type="camera" name="camera1">
      <update_rate>30.0</update_rate>
      <camera name="head">
        <horizontal_fov>1.3962634</horizontal_fov>
        <image>
          <width>800</width>
          <height>800</height>
          <format>R8G8B8</format>
        </image>
        <clip>
          <near>0.02</near>
          <far>300</far>
        </clip>
        <noise>
          <type>gaussian</type>
          <!-- Noise is sampled independently per pixel on each frame.
               That pixel's noise value is added to each of its color
               channels, which at that point lie in the range [0,1]. -->
          <mean>0.0</mean>
          <stddev>0.007</stddev>
        </noise>
      </camera>
      <plugin name="camera_controller" filename="libgazebo_ros_camera.so">
        <alwaysOn>true</alwaysOn>
        <updateRate>0.0</updateRate>
        <cameraName>rrbot/camera1</cameraName>
        <imageTopicName>image_raw</imageTopicName>
        <cameraInfoTopicName>camera_info</cameraInfoTopicName>
        <frameName>camera_link</frameName>
        <hackBaseline>0.07</hackBaseline>
        <distortionK1>0.0</distortionK1>
        <distortionK2>0.0</distortionK2>
        <distortionK3>0.0</distortionK3>
        <distortionT1>0.0</distortionT1>
        <distortionT2>0.0</distortionT2>
      </plugin>
    </sensor>
  </gazebo>


  <!-- <gazebo> 
    <plugin name="gazebo_ros_control" filename="libgazebo_ros_control.so">
      <robotNamespace>/simple_model</robotNamespace>
      <legacyModeNS>true</legacyModeNS>
      <robotSimType>gazebo_ros_control/DefaultRobotHWSim</robotSimType>
    </plugin>
  </gazebo>-->
  
</robot>
